Workbook

Sheet README_Demo_Guide
A1: Ford Manufacturing Operations Copilot in Excel Demo
A3: FICTIONAL SYNTHETIC TRAINING DATA — NOT FOR OPERATIONAL USE
A5: Section | B5: Details
A6: Purpose | B6: Demonstrate Microsoft Copilot in Excel across workbook orientation, data cleanup, formula generation, trends, quality and risk analysis, dashboard creation, and advanced forecasting.
A7: Scenario | B7: You are a manufacturing operations analyst reviewing plant throughput, supplier performance, quality, delivery, warranty signals, launch readiness, and operational risk.
A8: Dataset note | B8: All plants, suppliers, programs, values, records, incidents, and outcomes are fictional synthetic data created for training. This workbook does not represent Ford production data, policy, performance, vehicles, plants, suppliers, or operational requirements.
A9: Recommended sequence | B9: Start with workbook orientation, clean Operations Data, add calculated columns, analyze trends, review Quality Risk, build/extend the Summary dashboard, then use Python for forecasting and clustering.
A10: Primary sheets | B10: Operations Data (600 rows), Quality Risk (240 rows), Summary, Weekly Trend, Lookup, Demo Prompts, Intentional Issues.
A11: Copilot readiness | B11: Data is formatted as Excel tables. Derived fields use formulas. Intentional quality issues and outliers are included for cleanup demonstrations.

Sheet Lookup
A1: Category | B1: Value | C1: Description
A2: Plant | B2: Dearborn Assembly | C2: Fictional manufacturing location
A3: Plant | B3: Kansas City Assembly | C3: Fictional manufacturing location
A4: Plant | B4: Louisville Assembly | C4: Fictional manufacturing location
A5: Plant | B5: Michigan Assembly | C5: Fictional manufacturing location
A6: Plant | B6: Oakville Assembly | C6: Fictional manufacturing location
A7: Vehicle Program | B7: Electric SUV | C7: Fictional vehicle program
A8: Vehicle Program | B8: Pickup Truck | C8: Fictional vehicle program
A9: Vehicle Program | B9: Commercial Van | C9: Fictional vehicle program
A10: Vehicle Program | B10: Performance SUV | C10: Fictional vehicle program
A11: Vehicle Program | B11: Hybrid Utility | C11: Fictional vehicle program
A12: Supplier | B12: Blue Harbor Components | C12: Fictional supplier
... A23: Component | B23: Thermal Interface Assembly | C23: Synthetic component category

Sheet Operations Data
A1: Record ID | B1: Week Start | C1: Month | D1: Plant | E1: Region | F1: Vehicle Program | G1: Shift | H1: Supplier | I1: Component | J1: Units Planned | K1: Units Produced | L1: Defects | M1: Rework Units | N1: On-Time Shipments | O1: Inspection Hours | P1: Downtime Hours | Q1: Supplier Confirmation | R1: Missing Calibration Flag | S1: Saturday Coverage | T1: Customer Complaints | U1: Warranty Claims | V1: Unit Cost ($) | W1: Scrap Cost ($) | X1: Notes | Y1: Defect Rate | Z1: On-Time % | AA1: Throughput Gap | AB1: Estimated Scrap Impact ($) | AC1: Operational Risk Score | AD1: Risk Band | AE1: Leadership Attention
A2: OPS-0001 | B2: 46027 | C2: Jan | D2: Louisville Assembly | E2: North America East | F2: Commercial Van | G2: Swing | H2: Cedar Forge Systems | I2: Seat Control Module | J2: 1026 | K2: 952 | L2: 23 | M2: 12 | N2: 926 | O2: 36.1 | P2: 8.3 | Q2: Confirmed | R2: No | S2: Not Required | T2: 7 | U2: 2 | V2: 90.27 | W2: 1506.93 | X2: Awaiting supplier confirmation | Y2: =IFERROR(L2/K2,0) -> 0.024159664 | Z2: =IFERROR(N2/K2,0) -> 0.97268908 | AA2: =J2-K2 -> 74 | AB2: =L2*V2 -> 2076.21 | AC2: =ROUND(MIN(100,(Y2*1000)+(1-Z2)*45+(P2*1.3)+IF(Q2="Late",18,IF(Q2="Pending",10,0))+IF(R2="Yes",20,0)+IF(S2="Decision Required",12,0)),1) -> 36.2 | AD2: =IF(AC2>=65,"High",IF(AC2>=40,"Medium","Low")) -> Low | AE2: =IF(OR(AD2="High",Q2="Late",R2="Yes",S2="Decision Required"),"Yes","No") -> No
A3: OPS-0002 | B3: 46027 | C3: Jan | D3: Michigan Assembly | E3: North America East | F3: Pickup Truck | G3: Day | H3: Pioneer Circuit Works | I3: Thermal Interface Assembly | J3: 1071 | K3: 1026 | L3: 13 | M3: 6 | N3: 984 | O3: 20.3 | P3: 14.3 | Q3: Late | R3: No | S3: Not Required | T3: 6 | U3: 0 | V3: 356.41 | W3: 1548.18 | X3: Review supplier batch | Y3: =IFERROR(L3/K3,0) -> 0.012670565 | Z3: =IFERROR(N3/K3,0) -> 0.95906433 | AA3: =J3-K3 -> 45 | AB3: =L3*V3 -> 4633.33 | AC3: =ROUND(MIN(100,(Y3*1000)+(1-Z3)*45+(P3*1.3)+IF(Q3="Late",18,IF(Q3="Pending",10,0))+IF(R3="Yes",20,0)+IF(S3="Decision Required",12,0)),1) -> 51.1 | AD3: =IF(AC3>=65,"High",IF(AC3>=40,"Medium","Low")) -> Medium | AE3: =IF(OR(AD3="High",Q3="Late",R3="Yes",S3="Decision Required"),"Yes","No") -> Yes
A4: OPS-0003 | B4: 46027 | C4: Jan | D4: Oakville Assembly | E4: Canada | F4: Hybrid Utility | G4: Night | H4: Atlas Thermal Solutions | I4: Seat Control Module | J4: 1025 | K4: 947 | L4: 19 | M4: 13 | N4: 945 | O4: 34.2 | P4: 2.9 | Q4: Confirmed | R4: No | S4: Not Required | T4: 8 | U4: 0 | V4: 164.46 | W4: 1819.22 | X4: Leadership decision required | Y4: =IFERROR(L4/K4,0) -> 0.020063358 | Z4: =IFERROR(N4/K4,0) -> 0.99788807 | AA4: =J4-K4 -> 78 | AB4: =L4*V4 -> 3124.74 | AC4: =ROUND(MIN(100,(Y4*1000)+(1-Z4)*45+(P4*1.3)+IF(Q4="Late",18,IF(Q4="Pending",10,0))+IF(R4="Yes",20,0)+IF(S4="Decision Required",12,0)),1) -> 23.9 | AD4: =IF(AC4>=65,"High",IF(AC4>=40,"Medium","Low")) -> Low | AE4: =IF(OR(AD4="High",Q4="Late",R4="Yes",S4="Decision Required"),"Yes","No") -> No
A5: OPS-0004 | B5: 46027 | C5: Jan | D5: Kansas City Assembly | E5: North America Central | F5: Hybrid Utility | G5: Night | H5: Blue Harbor Components | I5: Thermal Interface Assembly | J5: 966 | K5: 844 | L5: 24 | M5: 16 | N5: 803 | O5: 33.9 | P5: 17 | Q5: Confirmed | R5: No | S5: Not Required | T5: 3 | U5: 2 | V5: 392.87 | W5: 3271.13 | X5: Normal variation | Y5: =IFERROR(L5/K5,0) -> 0.028436019 | Z5: =IFERROR(N5/K5,0) -> 0.9514218 | AA5: =J5-K5 -> 122 | AB5: =L5*V5 -> 9428.88 | AC5: =ROUND(MIN(100,(Y5*1000)+(1-Z5)*45+(P5*1.3)+IF(Q5="Late",18,IF(Q5="Pending",10,0))+IF(R5="Yes",20,0)+IF(S5="Decision Required",12,0)),1) -> 52.7 | AD5: =IF(AC5>=65,"High",IF(AC5>=40,"Medium","Low")) -> Medium | AE5: =IF(OR(AD5="High",Q5="Late",R5="Yes",S5="Decision Required"),"Yes","No") -> No
A6: OPS-0005 | B6: 46027 | C6: Jan | D6: Kansas City Assembly | E6: North America Central | F6: Performance SUV | G6: Night | H6: Pioneer Circuit Works | I6: Drive Unit Housing | J6: 1339 | K6: 1316 | L6: 41 | M6: 16 | N6: 1196 | O6: 52 | P6: 9.2 | Q6: Pending | R6: No | S6: Not Required | T6: 8 | U6: 1 | V6: 400.08 | W6: 7278.3 | X6: Normal variation | Y6: =IFERROR(L6/K6,0) -> 0.031155015 | Z6: =IFERROR(N6/K6,0) -> 0.90881459 | AA6: =J6-K6 -> 23 | AB6: =L6*V6 -> 16403.28 | AC6: =ROUND(MIN(100,(Y6*1000)+(1-Z6)*45+(P6*1.3)+IF(Q6="Late",18,IF(Q6="Pending",10,0))+IF(R6="Yes",20,0)+IF(S6="Decision Required",12,0)),1) -> 57.2 | AD6: =IF(AC6>=65,"High",IF(AC6>=40,"Medium","Low")) -> Medium | AE6: =IF(OR(AD6="High",Q6="Late",R6="Yes",S6="Decision Required"),"Yes","No") -> No
A7: OPS-0006 | B7: 46027 | C7: Jan | D7: Kansas City Assembly | E7: North America Central | F7: Commercial Van | G7: Swing | H7: Cedar Forge Systems | I7: Infotainment Harness | J7: 1523 | K7: 1336 | L7: 46 | M7: 16 | N7: 1213 | O7: 19.8 | P7: 0 | Q7: Pending | R7: No | S7: Not Required | T7: 8 | U7: 4 | V7: 151.39 | W7: 2659.53 | X7: Review supplier batch | Y7: =IFERROR(L7/K7,0) -> 0.034431138 | Z7: =IFERROR(N7/K7,0) -> 0.90793413 | AA7: =J7-K7 -> 187 | AB7: =L7*V7 -> 6963.94 | AC7: =ROUND(MIN(100,(Y7*1000)+(1-Z7)*45+(P7*1.3)+IF(Q7="Late",18,IF(Q7="Pending",10,0))+IF(R7="Yes",20,0)+IF(S7="Decision Required",12,0)),1) -> 48.6 | AD7: =IF(AC7>=65,"High",IF(AC7>=40,"Medium","Low")) -> Medium | AE7: =IF(OR(AD7="High",Q7="Late",R7="Yes",S7="Decision Required"),"Yes","No") -> No
A8: OPS-0007 | B8: 46027 | C8: Jan | D8: Dearborn Assembly | E8: North America East | F8: Performance SUV | G8: Swing | H8: Pioneer Circuit Works | I8: Torque Sensor | J8: 1155 | K8: 1069 | L8: 38 | M8: 16 | N8: 980 | O8: 30.9 | P8: 1.6 | Q8: Confirmed | R8: Yes | S8: Added | T8: 6 | U8: 2 | V8: 105.83 | W8: 1867.81 | X8: Normal variation | Y8: =IFERROR(L8/K8,0) -> 0.03554724 | Z8: =IFERROR(N8/K8,0) -> 0.91674462 | AA8: =J8-K8 -> 86 | AB8: =L8*V8 -> 4021.54 | AC8: =ROUND(MIN(100,(Y8*1000)+(1-Z8)*45+(P8*1.3)+IF(Q8="Late",18,IF(Q8="Pending",10,0))+IF(R8="Yes",20,0)+IF(S8="Decision Required",12,0)),1) -> 61.4 | AD8: =IF(AC8>=65,"High",IF(AC8>=40,"Medium","Low")) -> Medium | AE8: =IF(OR(AD8="High",Q8="Late",R8="Yes",S8="Decision Required"),"Yes","No") -> Yes
A9: OPS-0008 | B9: 46027 | C9: Jan | D9: Dearborn Assembly | E9: North America East | F9: Electric SUV | G9: Day | H9: Northstar Seating | I9: Thermal Interface Assembly | J9: 1323 | K9: 1317 | L9: 36 | M9: 21 | N9: 1303 | O9: 38.1 | P9: 0 | Q9: Confirmed | R9: No | S9: Not Required | T9: 5 | U9: 5 | V9: 294.73 | W9: 6670.89 | X9: Normal variation | Y9: =IFERROR(L9/K9,0) -> 0.027334852 | Z9: =IFERROR(N9/K9,0) -> 0.98936978 | AA9: =J9-K9 -> 6 | AB9: =L9*V9 -> 10610.28 | AC9: =ROUND(MIN(100,(Y9*1000)+(1-Z9)*45+(P9*1.3)+IF(Q9="Late",18,IF(Q9="Pending",10,0))+IF(R9="Yes",20,0)+IF(S9="Decision Required",12,0)),1) -> 27.8 | AD9: =IF(AC9>=65,"High",IF(AC9>=40,"Medium","Low")) -> Low | AE9: =IF(OR(AD9="High",Q9="Late",R9="Yes",S9="Decision Required"),"Yes","No") -> No
A10: OPS-0009 | B10: 46027 | C10: Jan | D10: Dearborn Assembly | E10: North America East | F10: Commercial Van | G10: Day | H10: Atlas Thermal Solutions | I10: Drive Unit Housing | J10: 848 | K10: 872 | L10: 23 | M10: 11 | N10: 795 | O10: 70.8 | P10: 5.1 | Q10: Confirmed | R10: No | S10: Not Required | T10: 5 | U10: 0 | V10: 166.31 | W10: 1713.42 | X10: Review supplier batch | Y10: =IFERROR(L10/K10,0) -> 0.026376147 | Z10: =IFERROR(N10/K10,0) -> 0.91169725 | AA10: =J10-K10 -> -24 | AB10: =L10*V10 -> 3825.13 | AC10: =ROUND(MIN(100,(Y10*1000)+(1-Z10)*45+(P10*1.3)+IF(Q10="Late",18,IF(Q10="Pending",10,0))+IF(R10="Yes",20,0)+IF(S10="Decision Required",12,0)),1) -> 37 | AD10: =IF(AC10>=65,"High",IF(AC10>=40,"Medium","Low")) -> Low | AE10: =IF(OR(AD10="High",Q10="Late",R10="Yes",S10="Decision Required"),"Yes","No") -> No
A11: OPS-0010 | B11: 46027 | C11: Jan | D11: Oakville Assembly | E11: Canada | F11: Hybrid Utility | G11: Day | H11: Blue Harbor Components | I11: Drive Unit Housing | J11: 1394 | K11: 1406 | L11: 13 | M11: 6 | N11: 1290 | O11: 58.4 | P11: 14.7 | Q11: Late | R11: No | S11: Not Required | T11: 0 | U11: 3 | V11: 85 | W11: 595.31 | X11: Normal variation | Y11: =IFERROR(L11/K11,0) -> 0.0092460882 | Z11: =IFERROR(N11/K11,0) -> 0.91749644 | AA11: =J11-K11 -> -12 | AB11: =L11*V11 -> 1105 | AC11: =ROUND(MIN(100,(Y11*1000)+(1-Z11)*45+(P11*1.3)+IF(Q11="Late",18,IF(Q11="Pending",10,0))+IF(R11="Yes",20,0)+IF(S11="Decision Required",12,0)),1) -> 50.1 | AD11: =IF(AC11>=65,"High",IF(AC11>=40,"Medium","Low")) -> Medium | AE11: =IF(OR(AD11="High",Q11="Late",R11="Yes",S11="Decision Required"),"Yes","No") -> Yes
A12: OPS-0011 | B12: 46027 | C12: Jan | D12: Michigan Assembly | E12: North America East | F12: Commercial Van | G12: Night | H12: Vector Embedded | I12: Torque Sensor | J12: 1182 | K12: 1166 | L12: 40 | M12: 25 | N12: 1140 | O12: 18.2 | P12: 13.7 | Q12: Late | R12: No | S12: Not Required | T12: 7 | U12: 4 | V12: 123.28 | W12: 3703.07 | X12: Normal variation | Y12: =IFERROR(L12/K12,0) -> 0.034305317 | Z12: =IFERROR(N12/K12,0) -> 0.97770154 | AA12: =J12-K12 -> 16 | AB12: =L12*V12 -> 4931.2 | AC12: =ROUND(MIN(100,(Y12*1000)+(1-Z12)*45+(P12*1.3)+IF(Q12="Late",18,IF(Q12="Pending",10,0))+IF(R12="Yes",20,0)+IF(S12="Decision Required",12,0)),1) -> 71.1 | AD12: =IF(AC12>=65,"High",IF(AC12>=40,"Medium","Low")) -> High | AE12: =IF(OR(AD12="High",Q12="Late",R12="Yes",S12="Decision Required"),"Yes","No") -> Yes
A13: OPS-0012 | B13: 46027 | C13: Jan | D13: Oakville Assembly | E13: Canada | F13: Hybrid Utility | G13: Swing | H13: Blue Harbor Components | I13: Battery Controller | J13: 1232 | K13: 1130 | L13: 20 | M13: 7 | N13: 1039 | O13: 36.9 | P13: 7.4 | Q13: Late | R13: No | S13: Not Required | T13: 5 | U13: 4 | V13: 452.74 | W13: 7079.36 | X13: Normal variation | Y13: =IFERROR(L13/K13,0) -> 0.017699115 | Z13: =IFERROR(N13/K13,0) -> 0.91946903 | AA13: =J13-K13 -> 102 | AB13: =L13*V13 -> 9054.8 | AC13: =ROUND(MIN(100,(Y13*1000)+(1-Z13)*45+(P13*1.3)+IF(Q13="Late",18,IF(Q13="Pending",10,0))+IF(R13="Yes",20,0)+IF(S13="Decision Required",12,0)),1) -> 48.9 | AD13: =IF(AC13>=65,"High",IF(AC13>=40,"Medium","Low")) -> Medium | AE13: =IF(OR(AD13="High",Q13="Late",R13="Yes",S13="Decision Required"),"Yes","No") -> Yes
... A519: OPS-0518 | B519: 46265 | C519: Aug | D519: Louisville Assembly | E519: North America East | F519: Electric SUV | G519: Night | H519: Northstar Seating | I519: Torque Sensor | J519: 1001 | K519: 895 | L519: 20 | M519: 14 | N519: 849 | O519: 22.3 | P519: 5.9 | Q519: Confirmed | R519: No | S519: Not Required | T519: 2 | U519: 2 | V519: 278.54 | W519: 4072.57 | X519: Normal variation | Y519: =IFERROR(L519/K519,0) -> 0.022346369 | Z519: =IFERROR(N519/K519,0) -> 0.94860335 | AA519: =J519-K519 -> 106 | AB519: =L519*V519 -> 5570.8 | AC519: =ROUND(MIN(100,(Y519*1000)+(1-Z519)*45+(P519*1.3)+IF(Q519="Late",18,IF(Q519="Pending",10,0))+IF(R519="Yes",20,0)+IF(S519="Decision Required",12,0)),1) -> 32.3 | AD519: =IF(AC519>=65,"High",IF(AC519>=40,"Medium","Low")) -> Low | AE519: =IF(OR(AD519="High",Q519="Late",R519="Yes",S519="Decision Required"),"Yes","No") -> No
A520: OPS-0119 | B520: 46076 | C520: Feb | D520: Michigan Assembly | E520: North America East | F520: Hybrid Utility | G520: Night | H520: Vector Embedded | I520: Infotainment Harness | J520: 1481 | K520: 1581 | L520: 77 | M520: 36 | N520: 1488 | O520: 43.2 | P520: 5.5 | Q520: Confirmed | R520: No | S520: Not Required | T520: 17 | U520: 6 | V520: 182.99 | W520: 9128.33 | X520: Normal variation | Y520: =IFERROR(L120/K120,0) -> 0.048703352 | Z520: =IFERROR(N120/K120,0) -> 0.94117647 | AA520: =J120-K120 -> -100 | AB520: =L120*V120 -> 14090.23 | AC520: =ROUND(MIN(100,(Y120*1000)+(1-Z120)*45+(P120*1.3)+IF(Q120="Late",18,IF(Q120="Pending",10,0))+IF(R120="Yes",20,0)+IF(S120="Decision Required",12,0)),1) -> 58.5 | AD520: =IF(AC120>=65,"High",IF(AC120>=40,"Medium","Low")) -> Medium | AE520: =IF(OR(AD120="High",Q120="Late",R120="Yes",S120="Decision Required"),"Yes","No") -> No
A521: OPS-0520 | B521: 46265 | C521: Aug | D521: Michigan Assembly | E521: North America East | F521: Commercial Van | G521: Swing | H521: Cedar Forge Systems | I521: Battery Controller | J521: 986 | K521: 927 | L521: 18 | M521: 14 | N521: 914 | O521: 41.3 | P521: 4.2 | Q521: Confirmed | R521: No | S521: Not Required | T521: 0 | U521: 6 | V521: 151.2 | W521: 1809.19 | X521: Throughput recovery in progress | Y521: =IFERROR(L521/K521,0) -> 0.019417476 | Z521: =IFERROR(N521/K521,0) -> 0.98597627 | AA521: =J521-K521 -> 59 | AB521: =L521*V521 -> 2721.6 | AC521: =ROUND(MIN(100,(Y521*1000)+(1-Z521)*45+(P521*1.3)+IF(Q521="Late",18,IF(Q521="Pending",10,0))+IF(R521="Yes",20,0)+IF(S521="Decision Required",12,0)),1) -> 25.5 | AD521: =IF(AC521>=65,"High",IF(AC521>=40,"Medium","Low")) -> Low | AE521: =IF(OR(AD521="High",Q521="Late",R521="Yes",S521="Decision Required"),"Yes","No") -> No
A522: OPS-0521 | B522: 46265 | C522: Aug | D522: Louisville Assembly | E522: North America East | F522: Performance SUV | G522: Swing | H522: Vector Embedded | I522: Thermal Interface Assembly | J522: 1350 | K522: 1157 | L522: 25 | M522: 9 | N522: 1109 | O522: 63.8 | P522: 8.4 | Q522: Pending | R522: No | S522: Not Required | T522: 5 | U522: 3 | V522: 131.21 | W522: 1267.05 | X522: Normal variation | Y522: =IFERROR(L522/K522,0) -> 0.021607606 | Z522: =IFERROR(N522/K522,0) -> 0.9585134 | AA522: =J522-K522 -> 193 | AB522: =L522*V522 -> 3280.25 | AC522: =ROUND(MIN(100,(Y522*1000)+(1-Z522)*45+(P522*1.3)+IF(Q522="Late",18,IF(Q522="Pending",10,0))+IF(R522="Yes",20,0)+IF(S522="Decision Required",12,0)),1) -> 44.4 | AD522: =IF(AC522>=65,"High",IF(AC522>=40,"Medium","Low")) -> Medium | AE522: =IF(OR(AD522="High",Q522="Late",R522="Yes",S522="Decision Required"),"Yes","No") -> No
A523: OPS-0522 | B523: 46265 | C523: Aug | D523: Michigan Assembly | E523: North America East | F523: Electric SUV | G523: Night | H523: Pioneer Circuit Works | I523: Seat Control Module | J523: 839 | K523: 825 | L523: 28 | M523: 16 | N523: 806 | O523: 29.2 | P523: 15 | Q523: Late | R523: No | S523: Decision Required | T523: 4 | U523: 3 | V523: 134.59 | W523: 1463.87 | X523: Normal variation | Y523: =IFERROR(L523/K523,0) -> 0.033939394 | Z523: =IFERROR(N523/K523,0) -> 0.9769697 | AA523: =J523-K523 -> 14 | AB523: =L523*V523 -> 3768.52 | AC523: =ROUND(MIN(100,(Y523*1000)+(1-Z523)*45+(P523*1.3)+IF(Q523="Late",18,IF(Q523="Pending",10,0))+IF(R523="Yes",20,0)+IF(S523="Decision Required",12,0)),1) -> 84.5 | AD523: =IF(AC523>=65,"High",IF(AC523>=40,"Medium","Low")) -> High | AE523: =IF(OR(AD523="High",Q523="Late",R523="Yes",S523="Decision Required"),"Yes","No") -> Yes
A524: OPS-0523 | B524: 46265 | C524: Aug | D524: Michigan Assembly | E524: North America East | F524: Commercial Van | G524: Night | H524: Vector Embedded | I524: Torque Sensor | J524: 862 | K524: 771 | L524: 22 | M524: 12 | N524: 692 | O524: 62 | P524: 9.8 | Q524: Late | R524: No | S524: Not Required | T524: 3 | U524: 0 | V524: 207.4 | W524: 3519.96 | X524: Normal variation | Y524: =IFERROR(L524/K524,0) -> 0.028534371 | Z524: =IFERROR(N524/K524,0) -> 0.89753567 | AA524: =J524-K524 -> 91 | AB524: =L524*V524 -> 4562.8 | AC524: =ROUND(MIN(100,(Y524*1000)+(1-Z524)*45+(P524*1.3)+IF(Q524="Late",18,IF(Q524="Pending",10,0))+IF(R524="Yes",20,0)+IF(S524="Decision Required",12,0)),1) -> 63.9 | AD524: =IF(AC524>=65,"High",IF(AC524>=40,"Medium","Low")) -> Medium | AE524: =IF(OR(AD524="High",Q524="Late",R524="Yes",S524="Decision Required"),"Yes","No") -> Yes
A525: OPS-0524 | B525: 46265 | C525: Aug | D525: Oakville Assembly | E525: Canada | F525: Pickup Truck | G525: Swing | H525: Cedar Forge Systems | I525: Seat Control Module | J525: 975 | K525: 885 | L525: 19 | M525: 14 | N525: 801 | O525: 66.1 | P525: 17.4 | Q525: Pending | R525: No | S525: Not Required | T525: 0 | U525: 3 | V525: 135.26 | W525: 1912.47 | X525: Normal variation | Y525: =IFERROR(L525/K525,0) -> 0.021468927 | Z525: =IFERROR(N525/K525,0) -> 0.90508475 | AA525: =J525-K525 -> 90 | AB525: =L525*V525 -> 2569.94 | AC525: =ROUND(MIN(100,(Y525*1000)+(1-Z525)*45+(P525*1.3)+IF(Q525="Late",18,IF(Q525="Pending",10,0))+IF(R525="Yes",20,0)+IF(S525="Decision Required",12,0)),1) -> 58.4 | AD525: =IF(AC525>=65,"High",IF(AC525>=40,"Medium","Low")) -> Medium | AE525: =IF(OR(AD525="High",Q525="Late",R525="Yes",S525="Decision Required"),"Yes","No") -> No
A526: OPS-0525 | B526: 46265 | C526: Aug | D526: Louisville Assembly | E526: North America East | F526: Commercial Van | G526: Day | H526: Vector Embedded | I526: Infotainment Harness | J526: 1070 | K526: 1008 | L526: 36 | M526: 23 | N526: 998 | O526: 62.9 | P526: 5.5 | Q526: Confirmed | R526: No | S526: Not Required | T526: 6 | U526: 5 | V526: 80.76 | W526: 2203.89 | X526: Awaiting supplier confirmation | Y526: =IFERROR(L526/K526,0) -> 0.035714286 | Z526: =IFERROR(N526/K526,0) -> 0.99007937 | AA526: =J526-K526 -> 62 | AB526: =L526*V526 -> 2907.36 | AC526: =ROUND(MIN(100,(Y526*1000)+(1-Z526)*45+(P526*1.3)+IF(Q526="Late",18,IF(Q526="Pending",10,0))+IF(R526="Yes",20,0)+IF(S526="Decision Required",12,0)),1) -> 43.3 | AD526: =IF(AC526>=65,"High",IF(AC526>=40,"Medium","Low")) -> Medium | AE526: =IF(OR(AD526="High",Q526="Late",R526="Yes",S526="Decision Required"),"Yes","No") -> No
A527: OPS-0526 | B527: 46272 | C527: Sep | D527: Louisville Assembly | E527: North America East | F527: Hybrid Utility | G527: Day | H527: Cedar Forge Systems | I527: Torque Sensor | J527: 952 | K527: 867 | L527: 18 | M527: 7 | N527: 807 | O527: 75.5 | P527: 6.5 | Q527: Pending | R527: No | S527: Decision Required | T527: 7 | U527: 0 | V527: 156.47 | W527: 2157.84 | X527: Throughput recovery in progress | Y527: =IFERROR(L527/K527,0) -> 0.020761246 | Z527: =IFERROR(N527/K527,0) -> 0.93079585 | AA527: =J527-K527 -> 85 | AB527: =L527*V527 -> 2816.46 | AC527: =ROUND(MIN(100,(Y527*1000)+(1-Z527)*45+(P527*1.3)+IF(Q527="Late",18,IF(Q527="Pending",10,0))+IF(R527="Yes",20,0)+IF(S527="Decision Required",12,0)),1) -> 54.3 | AD527: =IF(AC527>=65,"High",IF(AC527>=40,"Medium","Low")) -> Medium | AE527: =IF(OR(AD527="High",Q527="Late",R527="Yes",S527="Decision Required"),"Yes","No") -> Yes
A528: OPS-0527 | B528: 46272 | C528: Sep | D528: Dearborn Assembly | E528: North America East | F528: Performance SUV | G528: Night | H528: Northstar Seating | I528: Thermal Interface Assembly | J528: 1465 | K528: 1359 | L528: 47 | M528: 39 | N528: 1355 | O528: 69.6 | P528: 11.2 | Q528: Confirmed | R528: No | S528: Not Required | T528: 8 | U528: 5 | V528: 182.28 | W528: 5230.69 | X528: Throughput recovery in progress | Y528: =IFERROR(L528/K528,0) -> 0.034584253 | Z528: =IFERROR(N528/K528,0) -> 0.99705666 | AA528: =J528-K528 -> 106 | AB528: =L528*V528 -> 8567.16 | AC528: =ROUND(MIN(100,(Y528*1000)+(1-Z528)*45+(P528*1.3)+IF(Q528="Late",18,IF(Q528="Pending",10,0))+IF(R528="Yes",20,0)+IF(S528="Decision Required",12,0)),1) -> 49.3 | AD528: =IF(AC528>=65,"High",IF(AC528>=40,"Medium","Low")) -> Medium | AE528: =IF(OR(AD528="High",Q528="Late",R528="Yes",S528="Decision Required"),"Yes","No") -> No
A529: OPS-0528 | B529: 46272 | C529: Sep | D529: Oakville Assembly | E529: Canada | F529: Performance SUV | G529: Night | H529: Blue Harbor Components | I529: Battery Controller | J529: 1351 | K529: 1156 | L529: 40 | M529: 19 | N529: 1108 | O529: 29.7 | P529: 0 | Q529: Confirmed | R529: No | S529: Added | T529: 7 | U529: 5 | V529: 326.16 | W529: 7100.46 | X529: Normal variation | Y529: =IFERROR(L529/K529,0) -> 0.034602076 | Z529: =IFERROR(N529/K529,0) -> 0.95847751 | AA529: =J529-K529 -> 195 | AB529: =L529*V529 -> 13046.4 | AC529: =ROUND(MIN(100,(Y529*1000)+(1-Z529)*45+(P529*1.3)+IF(Q529="Late",18,IF(Q529="Pending",10,0))+IF(R529="Yes",20,0)+IF(S529="Decision Required",12,0)),1) -> 36.5 | AD529: =IF(AC529>=65,"High",IF(AC529>=40,"Medium","Low")) -> Low | AE529: =IF(OR(AD529="High",Q529="Late",R529="Yes",S529="Decision Required"),"Yes","No") -> No
A530: OPS-0529 | B530: 46272 | C530: Sep | D530: Kansas City Assembly | E530: North America Central | F530: Pickup Truck | G530: Swing | H530: Pioneer Circuit Works | I530: Drive Unit Housing | J530: 1167 | K530: 1022 | L530: 22 | M530: 16 | N530: 948 | O530: 54.9 | P530: 0 | Q530: Confirmed | R530: No | S530: Not Required | T530: 0 | U530: 2 | V530: 195.7 | W530: 1200.74 | X530: Calibration evidence incomplete | Y530: =IFERROR(L530/K530,0) -> 0.021526419 | Z530: =IFERROR(N530/K530,0) -> 0.92759295 | AA530: =J530-K530 -> 145 | AB530: =L530*V530 -> 4305.4 | AC530: =ROUND(MIN(100,(Y530*1000)+(1-Z530)*45+(P530*1.3)+IF(Q530="Late",18,IF(Q530="Pending",10,0))+IF(R530="Yes",20,0)+IF(S530="Decision Required",12,0)),1) -> 24.8 | AD530: =IF(AC530>=65,"High",IF(AC530>=40,"Medium","Low")) -> Low | AE530: =IF(OR(AD530="High",Q530="Late",R530="Yes",S530="Decision Required"),"Yes","No") -> No
A531: OPS-0530 | B531: 46272 | C531: Sep | D531: Kansas City Assembly | E531: North America Central | F531: Electric SUV | G531: Swing | H531: Atlas Thermal Solutions | I531: Seat Control Module | J531: 1017 | K531: 954 | L531: 25 | M531: 16 | N531: 847 | O531: 71.1 | P531: 1.7 | Q531: Late | R531: No | S531: Not Required | T531: 6 | U531: 4 | V531: 148.13 | W531: 1147.02 | X531: Review supplier batch | Y531: =IFERROR(L531/K531,0) -> 0.026205451 | Z531: =IFERROR(N531/K531,0) -> 0.88784067 | AA531: =J531-K531 -> 63 | AB531: =L531*V531 -> 3703.25 | AC531: =ROUND(MIN(100,(Y531*1000)+(1-Z531)*45+(P531*1.3)+IF(Q531="Late",18,IF(Q531="Pending",10,0))+IF(R531="Yes",20,0)+IF(S531="Decision Required",12,0)),1) -> 51.5 | AD531: =IF(AC531>=65,"High",IF(AC531>=40,"Medium","Low")) -> Medium | AE531: =IF(OR(AD531="High",Q531="Late",R531="Yes",S531="Decision Required"),"Yes","No") -> Yes
A532: OPS-0531 | B532: 46272 | C532: Sep | D532: Kansas City Assembly | E532: North America Central | F532: Pickup Truck | G532: Night | H532: Blue Harbor Components | I532: Seat Control Module | J532: 830 | K532: 771 | L532: 19 | M532: 12 | N532: 682 | O532: 55.7 | P532: 4.8 | Q532: Confirmed | R532: No | S532: Added | T532: 6 | U532: 1 | V532: 364.39 | W532: 2219.42 | X532: Leadership decision required | Y532: =IFERROR(L532/K532,0) -> 0.02464332 | Z532: =IFERROR(N532/K532,0) -> 0.8845655 | AA532: =J532-K532 -> 59 | AB532: =L532*V532 -> 6923.41 | AC532: =ROUND(MIN(100,(Y532*1000)+(1-Z532)*45+(P532*1.3)+IF(Q532="Late",18,IF(Q532="Pending",10,0))+IF(R532="Yes",20,0)+IF(S532="Decision Required",12,0)),1) -> 36.1 | AD532: =IF(AC532>=65,"High",IF(AC532>=40,"Medium","Low")) -> Low | AE532: =IF(OR(AD532="High",Q532="Late",R532="Yes",S532="Decision Required"),"Yes","No") -> No
... A574: OPS-0573 | B574: 46293 | C574: Sep | D574: Michigan Assembly | E574: North America East | F574: Hybrid Utility | G574: Night | H574: Cedar Forge Systems | I574: Drive Unit Housing | J574: 1057 | K574: 1020 | L574: 22 | M574: 17 | N574: 961 | O574: 53.3 | P574: 19 | Q574: Confirmed | R574: No | S574: Not Required | T574: 3 | U574: 2 | V574: 131.7 | W574: 751.15 | X574: Leadership decision required | Y574: =IFERROR(L574/K574,0) -> 0.021568627 | Z574: =IFERROR(N574/K574,0) -> 0.94215686 | AA574: =J574-K574 -> 37 | AB574: =L574*V574 -> 2897.4 | AC574: =ROUND(MIN(100,(Y574*1000)+(1-Z574)*45+(P574*1.3)+IF(Q574="Late",18,IF(Q574="Pending",10,0))+IF(R574="Yes",20,0)+IF(S574="Decision Required",12,0)),1) -> 48.9 | AD574: =IF(AC574>=65,"High",IF(AC574>=40,"Medium","Low")) -> Medium | AE574: =IF(OR(AD574="High",Q574="Late",R574="Yes",S574="Decision Required"),"Yes","No") -> No
A575: OPS-0244 | B575: 46139 | C575: Apr | D575: Dearborn Assembly | E575: North America East | F575: Electric SUV | G575: Night | H575: Pioneer Circuit Works | I575: Thermal Interface Assembly | J575: 1055 | K575: 957 | L575: 36 | M575: 25 | N575: 912 | O575: 25.7 | P575: 0 | Q575: Pending | R575: No | S575: Not Required | T575: 4 | U575: 4 | V575: 45.98 | W575: 846.05 | X575: Normal variation | Y575: =IFERROR(L245/K245,0) -> 0.037617555 | Z575: =IFERROR(N245/K245,0) -> 0.95297806 | AA575: =J245-K245 -> 98 | AB575: =L245*V245 -> 1655.28 | AC575: =ROUND(MIN(100,(Y245*1000)+(1-Z245)*45+(P245*1.3)+IF(Q245="Late",18,IF(Q245="Pending",10,0))+IF(R245="Yes",20,0)+IF(S245="Decision Required",12,0)),1) -> 49.7 | AD575: =IF(AC245>=65,"High",IF(AC245>=40,"Medium","Low")) -> Medium | AE575: =IF(OR(AD245="High",Q245="Late",R245="Yes",S245="Decision Required"),"Yes","No") -> No
A576: OPS-0575 | B576: 46293 | C576: Sep | D576: Kansas City Assembly | E576: North America Central | F576: Pickup Truck | G576: Night | H576: Northstar Seating | I576: Torque Sensor | J576: 1204 | K576: 1123 | L576: 30 | M576: 17 | N576: 993 | O576: 62.6 | P576: 0 | Q576: Late | R576: Yes | S576: Not Required | T576: 7 | U576: 1 | V576: 291.24 | W576: 6613.16 | X576: Normal variation | Y576: =IFERROR(L576/K576,0) -> 0.026714159 | Z576: =IFERROR(N576/K576,0) -> 0.88423865 | AA576: =J576-K576 -> 81 | AB576: =L576*V576 -> 8737.2 | AC576: =ROUND(MIN(100,(Y576*1000)+(1-Z576)*45+(P576*1.3)+IF(Q576="Late",18,IF(Q576="Pending",10,0))+IF(R576="Yes",20,0)+IF(S576="Decision Required",12,0)),1) -> 69.9 | AD576: =IF(AC576>=65,"High",IF(AC576>=40,"Medium","Low")) -> High | AE576: =IF(OR(AD576="High",Q576="Late",R576="Yes",S576="Decision Required"),"Yes","No") -> Yes
A577: OPS-0576 | B577: 46293 | C577: Sep | D577: Michigan Assembly | E577: North America East | F577: Performance SUV | G577: Swing | H577: Northstar Seating | I577: Thermal Interface Assembly | J577: 1307 | K577: 1257 | L577: 38 | M577: 20 | N577: 1236 | O577: 27.5 | P577: 0 | Q577: Confirmed | R577: No | S577: Not Required | T577: 3 | U577: 3 | V577: 198.36 | W577: 5166.52 | X577: Quality containment active | Y577: =IFERROR(L577/K577,0) -> 0.030230708 | Z577: =IFERROR(N577/K577,0) -> 0.98329356 | AA577: =J577-K577 -> 50 | AB577: =L577*V577 -> 7537.68 | AC577: =ROUND(MIN(100,(Y577*1000)+(1-Z577)*45+(P577*1.3)+IF(Q577="Late",18,IF(Q577="Pending",10,0))+IF(R577="Yes",20,0)+IF(S577="Decision Required",12,0)),1) -> 31 | AD577: =IF(AC577>=65,"High",IF(AC577>=40,"Medium","Low")) -> Low | AE577: =IF(OR(AD577="High",Q577="Late",R577="Yes",S577="Decision Required"),"Yes","No") -> No
A578: OPS-0577 | B578: 46293 | C578: Sep | D578: Dearborn Assembly | E578: North America East | F578: Hybrid Utility | G578: Swing | H578: Blue Harbor Components | I578: Torque Sensor | J578: 1162 | K578: 1093 | L578: 10 | M578: 3 | N578: 1047 | O578: 23 | P578: 7 | Q578: Confirmed | R578: Yes | S578: Decision Required | T578: 3 | U578: 3 | V578: 221.7 | W578: 1010.83 | X578: Normal variation | Y578: =IFERROR(L578/K578,0) -> 0.0091491308 | Z578: =IFERROR(N578/K578,0) -> 0.957914 | AA578: =J578-K578 -> 69 | AB578: =L578*V578 -> 2217 | AC578: =ROUND(MIN(100,(Y578*1000)+(1-Z578)*45+(P578*1.3)+IF(Q578="Late",18,IF(Q578="Pending",10,0))+IF(R578="Yes",20,0)+IF(S578="Decision Required",12,0)),1) -> 52.1 | AD578: =IF(AC578>=65,"High",IF(AC578>=40,"Medium","Low")) -> Medium | AE578: =IF(OR(AD578="High",Q578="Late",R578="Yes",S578="Decision Required"),"Yes","No") -> Yes
A579: OPS-0578 | B579: 46293 | C579: Sep | D579: Michigan Assembly | E579: North America East | F579: Commercial Van | G579: Day | H579: Atlas Thermal Solutions | I579: Seat Control Module | J579: 896 | K579: 838 | L579: 10 | M579: 7 | N579: 838 | O579: 68.1 | P579: 1 | Q579: Confirmed | R579: No | S579: Not Required | T579: 1 | U579: 1 | V579: 204.37 | W579: 1222.39 | X579: Normal variation | Y579: =IFERROR(L579/K579,0) -> 0.011933174 | Z579: =IFERROR(N579/K579,0) -> 1 | AA579: =J579-K579 -> 58 | AB579: =L579*V579 -> 2043.7 | AC579: =ROUND(MIN(100,(Y579*1000)+(1-Z579)*45+(P579*1.3)+IF(Q579="Late",18,IF(Q579="Pending",10,0))+IF(R579="Yes",20,0)+IF(S579="Decision Required",12,0)),1) -> 13.2 | AD579: =IF(AC579>=65,"High",IF(AC579>=40,"Medium","Low")) -> Low | AE579: =IF(OR(AD579="High",Q579="Late",R579="Yes",S579="Decision Required"),"Yes","No") -> No
A580: OPS-0579 | B580: 46293 | C580: Sep | D580: Louisville Assembly | E580: North America East | F580: Hybrid Utility | G580: Night | H580: Cedar Forge Systems | I580: Drive Unit Housing | J580: 1086 | K580: 973 | L580: 21 | M580: 11 | N580: 934 | O580: 27.5 | P580: 7.7 | Q580: Confirmed | R580: No | S580: Added | T580: 6 | U580: 4 | V580: 89.7 | W580: 1401.18 | X580: Quality containment active | Y580: =IFERROR(L580/K580,0) -> 0.021582734 | Z580: =IFERROR(N580/K580,0) -> 0.95991778 | AA580: =J580-K580 -> 113 | AB580: =L580*V580 -> 1883.7 | AC580: =ROUND(MIN(100,(Y580*1000)+(1-Z580)*45+(P580*1.3)+IF(Q580="Late",18,IF(Q580="Pending",10,0))+IF(R580="Yes",20,0)+IF(S580="Decision Required",12,0)),1) -> 33.4 | AD580: =IF(AC580>=65,"High",IF(AC580>=40,"Medium","Low")) -> Low | AE580: =IF(OR(AD580="High",Q580="Late",R580="Yes",S580="Decision Required"),"Yes","No") -> No
A581: OPS-0580 | B581: 46293 | C581: Sep | D581: Dearborn Assembly | E581: North America East | F581: Performance SUV | G581: Day | H581: Pioneer Circuit Works | I581: Infotainment Harness | J581: 1340 | K581: 1343 | L581: 45 | M581: 22 | N581: 1340 | O581: 66.8 | P581: 15.2 | Q581: Confirmed | R581: No | S581: Not Required | T581: 6 | U581: 5 | V581: 421.18 | W581: 11767.43 | X581: Throughput recovery in progress | Y581: =IFERROR(L581/K581,0) -> 0.033507074 | Z581: =IFERROR(N581/K581,0) -> 0.9977662 | AA581: =J581-K581 -> -3 | AB581: =L581*V581 -> 18953.1 | AC581: =ROUND(MIN(100,(Y581*1000)+(1-Z581)*45+(P581*1.3)+IF(Q581="Late",18,IF(Q581="Pending",10,0))+IF(R581="Yes",20,0)+IF(S581="Decision Required",12,0)),1) -> 53.4 | AD581: =IF(AC581>=65,"High",IF(AC581>=40,"Medium","Low")) -> Medium | AE581: =IF(OR(AD581="High",Q581="Late",R581="Yes",S581="Decision Required"),"Yes","No") -> No
A582: OPS-0581 | B582: 46293 | C582: Sep | D582: Michigan Assembly | E582: North America East | F582: Performance SUV | G582: Day | H582: Vector Embedded | I582: Infotainment Harness | J582: 812 | K582: 815 | L582: 29 | M582: 17 | N582: 738 | O582: 66.7 | P582: 0.8 | Q582: Confirmed | R582: No | S582: Not Required | T582: 5 | U582: 0 | V582: 324.51 | W582: 4531.7 | X582: Review supplier batch | Y582: =IFERROR(L582/K582,0) -> 0.035582822 | Z582: =IFERROR(N582/K582,0) -> 0.90552147 | AA582: =J582-K582 -> -3 | AB582: =L582*V582 -> 9410.79 | AC582: =ROUND(MIN(100,(Y582*1000)+(1-Z582)*45+(P582*1.3)+IF(Q582="Late",18,IF(Q582="Pending",10,0))+IF(R582="Yes",20,0)+IF(S582="Decision Required",12,0)),1) -> 40.9 | AD582: =IF(AC582>=65,"High",IF(AC582>=40,"Medium","Low")) -> Medium | AE582: =IF(OR(AD582="High",Q582="Late",R582="Yes",S582="Decision Required"),"Yes","No") -> No
A583: OPS-0582 | B583: 46293 | C583: Sep | D583: Kansas City Assembly | E583: North America Central | F583: Performance SUV | G583: Day | H583: Vector Embedded | I583: Seat Control Module | J583: 805 | K583: 708 | L583: 8 | M583: 4 | N583: 654 | O583: 26.7 | P583: 12.6 | Q583: Pending | R583: No | S583: Not Required | T583: 2 | U583: 0 | V583: 250.68 | W583: 699.87 | X583: Throughput recovery in progress | Y583: =IFERROR(L583/K583,0) -> 0.011299435 | Z583: =IFERROR(N583/K583,0) -> 0.92372881 | AA583: =J583-K583 -> 97 | AB583: =L583*V583 -> 2005.44 | AC583: =ROUND(MIN(100,(Y583*1000)+(1-Z583)*45+(P583*1.3)+IF(Q583="Late",18,IF(Q583="Pending",10,0))+IF(R583="Yes",20,0)+IF(S583="Decision Required",12,0)),1) -> 41.1 | AD583: =IF(AC583>=65,"High",IF(AC583>=40,"Medium","Low")) -> Medium | AE583: =IF(OR(AD583="High",Q583="Late",R583="Yes",S583="Decision Required"),"Yes","No") -> No
A584: OPS-0583 | B584: 46293 | C584: Sep | D584: Kansas City Assembly | E584: North America Central | F584: Commercial Van | G584: Day | H584: Pioneer Circuit Works | I584: Drive Unit Housing | J584: 948 | K584: 921 | L584: 18 | M584: 10 | N584: 859 | O584: 56.8 | P584: 7 | Q584: Confirmed | R584: No | S584: Not Required | T584: 0 | U584: 2 | V584: 441.67 | W584: 6200.15 | X584: Throughput recovery in progress | Y584: =IFERROR(L584/K584,0) -> 0.019543974 | Z584: =IFERROR(N584/K584,0) -> 0.93268187 | AA584: =J584-K584 -> 27 | AB584: =L584*V584 -> 7950.06 | AC584: =ROUND(MIN(100,(Y584*1000)+(1-Z584)*45+(P584*1.3)+IF(Q584="Late",18,IF(Q584="Pending",10,0))+IF(R584="Yes",20,0)+IF(S584="Decision Required",12,0)),1) -> 31.7 | AD584: =IF(AC584>=65,"High",IF(AC584>=40,"Medium","Low")) -> Low | AE584: =IF(OR(AD584="High",Q584="Late",R584="Yes",S584="Decision Required"),"Yes","No") -> No
A585: OPS-0584 | B585: 46293 | C585: Sep | D585: Louisville Assembly | E585: North America East | F585: Commercial Van | G585: Night | H585: Northstar Seating | I585: Drive Unit Housing | J585: 1419 | K585: 1276 | L585: 15 | M585: 8 | N585: 1222 | O585: 54.3 | P585: 9.6 | Q585: Confirmed | R585: No | S585: Not Required | T585: 3 | U585: 0 | V585: 149.98 | W585: 1726.56 | X585: Normal variation | Y585: =IFERROR(L585/K585,0) -> 0.011755486 | Z585: =IFERROR(N585/K585,0) -> 0.95768025 | AA585: =J585-K585 -> 143 | AB585: =L585*V585 -> 2249.7 | AC585: =ROUND(MIN(100,(Y585*1000)+(1-Z585)*45+(P585*1.3)+IF(Q585="Late",18,IF(Q585="Pending",10,0))+IF(R585="Yes",20,0)+IF(S585="Decision Required",12,0)),1) -> 26.1 | AD585: =IF(AC585>=65,"High",IF(AC585>=40,"Medium","Low")) -> Low | AE585: =IF(OR(AD585="High",Q585="Late",R585="Yes",S585="Decision Required"),"Yes","No") -> No
A586: OPS-0585 | B586: 46293 | C586: Sep | D586: Dearborn Assembly | E586: North America East | F586: Performance SUV | G586: Swing | H586: Atlas Thermal Solutions | I586: Battery Controller | J586: 1493 | K586: 1516 | L586: 67 | M586: 48 | N586: 1336 | O586: 48 | P586: 12.9 | Q586: Confirmed | R586: No | S586: Not Required | T586: 11 | U586: 5 | V586: 381.06 | W586: 13584.52 | X586: Normal variation | Y586: =IFERROR(L586/K586,0) -> 0.044195251 | Z586: =IFERROR(N586/K586,0) -> 0.88126649 | AA586: =J586-K586 -> -23 | AB586: =L586*V586 -> 25531.02 | AC586: =ROUND(MIN(100,(Y586*1000)+(1-Z586)*45+(P586*1.3)+IF(Q586="Late",18,IF(Q586="Pending",10,0))+IF(R586="Yes",20,0)+IF(S586="Decision Required",12,0)),1) -> 66.3 | AD586: =IF(AC586>=65,"High",IF(AC586>=40,"Medium","Low")) -> High | AE586: =IF(OR(AD586="High",Q586="Late",R586="Yes",S586="Decision Required"),"Yes","No") -> Yes
...

Sheet Quality Risk
A1: Risk ID | B1: Review Date | C1: Plant | D1: Vehicle Program | E1: Supplier | F1: Component | G1: Defect Trend | H1: Calibration Status | I1: Supplier Readiness | J1: Severity | K1: Likelihood | L1: Customer Impact | M1: Estimated Exposure ($) | N1: Days Open | O1: Risk Threshold | P1: Risk Score | Q1: Review Status | R1: Leadership Attention | S1: Recommended Follow-up
A2: RSK-0001 | B2: 46260 | C2: Oakville Assembly | D2: Commercial Van | E2: Vector Embedded | F2: Battery Controller | G2: Improving | H2: Complete | I2: Ready | J2: 1 | K2: 4 | L2: High | M2: 1282120 | N2: 72 | O2: 12 | P2: =J2*K2+IF(G2="Worsening",5,0)+IF(H2="Missing",5,IF(H2="Pending",2,0))+IF(I2="At Risk",5,IF(I2="Conditional",2,0)) -> 4 | Q2: =IF(P2>=O2,"Review Required",IF(P2>=O2*0.75,"Approaching Review","Monitor")) -> Monitor | R2: =IF(OR(L2="Critical",Q2="Review Required",H2="Missing"),"Yes","No") -> No | S2: =IF(H2="Missing","Validate calibration evidence",IF(G2="Worsening","Review defect trend and containment",IF(I2="At Risk","Escalate supplier readiness","Continue monitoring"))) -> Continue monitoring
A3: RSK-0002 | B3: 46279 | C3: Louisville Assembly | D3: Hybrid Utility | E3: Vector Embedded | F3: Thermal Interface Assembly | G3: Improving | H3: Pending | I3: At Risk | J3: 5 | K3: 2 | L3: Low | M3: 1775157 | N3: 72 | O3: 12 | P3: =J3*K3+IF(G3="Worsening",5,0)+IF(H3="Missing",5,IF(H3="Pending",2,0))+IF(I3="At Risk",5,IF(I3="Conditional",2,0)) -> 17 | Q3: =IF(P3>=O3,"Review Required",IF(P3>=O3*0.75,"Approaching Review","Monitor")) -> Review Required | R3: =IF(OR(L3="Critical",Q3="Review Required",H3="Missing"),"Yes","No") -> Yes | S3: =IF(H3="Missing","Validate calibration evidence",IF(G3="Worsening","Review defect trend and containment",IF(I3="At Risk","Escalate supplier readiness","Continue monitoring"))) -> Escalate supplier readiness
A4: RSK-0003 | B4: 46258 | C4: Kansas City Assembly | D4: Performance SUV | E4: Vector Embedded | F4: Thermal Interface Assembly | G4: Improving | H4: Complete | I4: Ready | J4: 2 | K4: 1 | L4: High | M4: 288041 | N4: 54 | O4: 12 | P4: =J4*K4+IF(G4="Worsening",5,0)+IF(H4="Missing",5,IF(H4="Pending",2,0))+IF(I4="At Risk",5,IF(I4="Conditional",2,0)) -> 2 | Q4: =IF(P4>=O4,"Review Required",IF(P4>=O4*0.75,"Approaching Review","Monitor")) -> Monitor | R4: =IF(OR(L4="Critical",Q4="Review Required",H4="Missing"),"Yes","No") -> No | S4: =IF(H4="Missing","Validate calibration evidence",IF(G4="Worsening","Review defect trend and containment",IF(I4="At Risk","Escalate supplier readiness","Continue monitoring"))) -> Continue monitoring
A5: RSK-0004 | B5: 46297 | C5: Oakville Assembly | D5: Pickup Truck | E5: Northstar Seating | F5: Torque Sensor | G5: Worsening | H5: Pending | I5: Ready | J5: 1 | K5: 4 | L5: High | M5: 354682 | N5: 6 | O5: 12 | P5: =J5*K5+IF(G5="Worsening",5,0)+IF(H5="Missing",5,IF(H5="Pending",2,0))+IF(I5="At Risk",5,IF(I5="Conditional",2,0)) -> 11 | Q5: =IF(P5>=O5,"Review Required",IF(P5>=O5*0.75,"Approaching Review","Monitor")) -> Approaching Review | R5: =IF(OR(L5="Critical",Q5="Review Required",H5="Missing"),"Yes","No") -> No | S5: =IF(H5="Missing","Validate calibration evidence",IF(G5="Worsening","Review defect trend and containment",IF(I5="At Risk","Escalate supplier readiness","Continue monitoring"))) -> Review defect trend and containment
A6: RSK-0005 | B6: 46255 | C6: Dearborn Assembly | D6: Hybrid Utility | E6: Atlas Thermal Solutions | F6: Torque Sensor | G6: Improving | H6: Complete | I6: At Risk | J6: 5 | K6: 4 | L6: High | M6: 599934 | N6: 20 | O6: 12 | P6: =J6*K6+IF(G6="Worsening",5,0)+IF(H6="Missing",5,IF(H6="Pending",2,0))+IF(I6="At Risk",5,IF(I6="Conditional",2,0)) -> 25 | Q6: =IF(P6>=O6,"Review Required",IF(P6>=O6*0.75,"Approaching Review","Monitor")) -> Review Required | R6: =IF(OR(L6="Critical",Q6="Review Required",H6="Missing"),"Yes","No") -> Yes | S6: =IF(H6="Missing","Validate calibration evidence",IF(G6="Worsening","Review defect trend and containment",IF(I6="At Risk","Escalate supplier readiness","Continue monitoring"))) -> Escalate supplier readiness
A7: RSK-0006 | B7: 46232 | C7: Dearborn Assembly | D7: Performance SUV | E7: Cedar Forge Systems | F7: Infotainment Harness | G7: Stable | H7: Complete | I7: Ready | J7: 1 | K7: 4 | L7: Medium | M7: 1912593 | N7: 21 | O7: 12 | P7: =J7*K7+IF(G7="Worsening",5,0)+IF(H7="Missing",5,IF(H7="Pending",2,0))+IF(I7="At Risk",5,IF(I7="Conditional",2,0)) -> 4 | Q7: =IF(P7>=O7,"Review Required",IF(P7>=O7*0.75,"Approaching Review","Monitor")) -> Monitor | R7: =IF(OR(L7="Critical",Q7="Review Required",H7="Missing"),"Yes","No") -> No | S7: =IF(H7="Missing","Validate calibration evidence",IF(G7="Worsening","Review defect trend and containment",IF(I7="At Risk","Escalate supplier readiness","Continue monitoring"))) -> Continue monitoring
A8: RSK-0007 | B8: 46225 | C8: Dearborn Assembly | D8: Commercial Van | E8: Vector Embedded | F8: Seat Control Module | G8: Stable | H8: Complete | I8: Ready | J8: 2 | K8: 2 | L8: Critical | M8: 297609 | N8: 14 | O8: 12 | P8: =J8*K8+IF(G8="Worsening",5,0)+IF(H8="Missing",5,IF(H8="Pending",2,0))+IF(I8="At Risk",5,IF(I8="Conditional",2,0)) -> 4 | Q8: =IF(P8>=O8,"Review Required",IF(P8>=O8*0.75,"Approaching Review","Monitor")) -> Monitor | R8: =IF(OR(L8="Critical",Q8="Review Required",H8="Missing"),"Yes","No") -> Yes | S8: =IF(H8="Missing","Validate calibration evidence",IF(G8="Worsening","Review defect trend and containment",IF(I8="At Risk","Escalate supplier readiness","Continue monitoring"))) -> Continue monitoring
A9: RSK-0008 | B9: 46285 | C9: Kansas City Assembly | D9: Pickup Truck | E9: Pioneer Circuit Works | F9: Thermal Interface Assembly | G9: Improving | H9: Complete | I9: Conditional | J9: 1 | K9: 4 | L9: Low | M9: 1911259 | N9: 47 | O9: 12 | P9: =J9*K9+IF(G9="Worsening",5,0)+IF(H9="Missing",5,IF(H9="Pending",2,0))+IF(I9="At Risk",5,IF(I9="Conditional",2,0)) -> 6 | Q9: =IF(P9>=O9,"Review Required",IF(P9>=O9*0.75,"Approaching Review","Monitor")) -> Monitor | R9: =IF(OR(L9="Critical",Q9="Review Required",H9="Missing"),"Yes","No") -> No | S9: =IF(H9="Missing","Validate calibration evidence",IF(G9="Worsening","Review defect trend and containment",IF(I9="At Risk","Escalate supplier readiness","Continue monitoring"))) -> Continue monitoring
A10: RSK-0009 | B10: 46037 | C10: Louisville Assembly | D10: Commercial Van | E10: Northstar Seating | F10: Battery Controller | G10: Improving | H10: Complete | I10: At Risk | J10: 3 | K10: 4 | L10: Low | M10: 206747 | N10: 69 | O10: 12 | P10: =J10*K10+IF(G10="Worsening",5,0)+IF(H10="Missing",5,IF(H10="Pending",2,0))+IF(I10="At Risk",5,IF(I10="Conditional",2,0)) -> 17 | Q10: =IF(P10>=O10,"Review Required",IF(P10>=O10*0.75,"Approaching Review","Monitor")) -> Review Required | R10: =IF(OR(L10="Critical",Q10="Review Required",H10="Missing"),"Yes","No") -> Yes | S10: =IF(H10="Missing","Validate calibration evidence",IF(G10="Worsening","Review defect trend and containment",IF(I10="At Risk","Escalate supplier readiness","Continue monitoring"))) -> Escalate supplier readiness
A11: RSK-0010 | B11: 46274 | C11: Oakville Assembly | D11: Electric SUV | E11: Cedar Forge Systems | F11: Drive Unit Housing | G11: Stable | H11: Pending | I11: Ready | J11: 3 | K11: 1 | L11: Critical | M11: 1300039 | N11: 49 | O11: 12 | P11: =J11*K11+IF(G11="Worsening",5,0)+IF(H11="Missing",5,IF(H11="Pending",2,0))+IF(I11="At Risk",5,IF(I11="Conditional",2,0)) -> 5 | Q11: =IF(P11>=O11,"Review Required",IF(P11>=O11*0.75,"Approaching Review","Monitor")) -> Monitor | R11: =IF(OR(L11="Critical",Q11="Review Required",H11="Missing"),"Yes","No") -> Yes | S11: =IF(H11="Missing","Validate calibration evidence",IF(G11="Worsening","Review defect trend and containment",IF(I11="At Risk","Escalate supplier readiness","Continue monitoring"))) -> Continue monitoring
A12: RSK-0011 | B12: 46221 | C12: Oakville Assembly | D12: Hybrid Utility | E12: Cedar Forge Systems | F12: Battery Controller | G12: Improving | H12: Complete | I12: Conditional | J12: 5 | K12: 3 | L12: High | M12: 1211303 | N12: 29 | O12: 12 | P12: =J12*K12+IF(G12="Worsening",5,0)+IF(H12="Missing",5,IF(H12="Pending",2,0))+IF(I12="At Risk",5,IF(I12="Conditional",2,0)) -> 17 | Q12: =IF(P12>=O12,"Review Required",IF(P12>=O12*0.75,"Approaching Review","Monitor")) -> Review Required | R12: =IF(OR(L12="Critical",Q12="Review Required",H12="Missing"),"Yes","No") -> Yes | S12: =IF(H12="Missing","Validate calibration evidence",IF(G12="Worsening","Review defect trend and containment",IF(I12="At Risk","Escalate supplier readiness","Continue monitoring"))) -> Continue monitoring
A13: RSK-0012 | B13: 46244 | C13: Kansas City Assembly | D13: Commercial Van | E13: Blue Harbor Components | F13: Battery Controller | G13: Improving | H13: Complete | I13: Ready | J13: 4 | K13: 1 | L13: Critical | M13: 863384 | N13: 23 | O13: 12 | P13: =J13*K13+IF(G13="Worsening",5,0)+IF(H13="Missing",5,IF(H13="Pending",2,0))+IF(I13="At Risk",5,IF(I13="Conditional",2,0)) -> 4 | Q13: =IF(P13>=O13,"Review Required",IF(P13>=O13*0.75,"Approaching Review","Monitor")) -> Monitor | R13: =IF(OR(L13="Critical",Q13="Review Required",H13="Missing"),"Yes","No") -> Yes | S13: =IF(H13="Missing","Validate calibration evidence",IF(G13="Worsening","Review defect trend and containment",IF(I13="At Risk","Escalate supplier readiness","Continue monitoring"))) -> Continue monitoring
... A241: RSK-0240 | B241: 46183 | C241: Louisville Assembly | D241: Electric SUV | E241: Cedar Forge Systems | F241: Seat Control Module | G241: Improving | H241: Complete | I241: Ready | J241: 4 | K241: 1 | L241: High | M241: 998812 | N241: 71 | O241: 12 | P241: =J241*K241+IF(G241="Worsening",5,0)+IF(H241="Missing",5,IF(H241="Pending",2,0))+IF(I241="At Risk",5,IF(I241="Conditional",2,0)) -> 4 | Q241: =IF(P241>=O241,"Review Required",IF(P241>=O241*0.75,"Approaching Review","Monitor")) -> Monitor | R241: =IF(OR(L241="Critical",Q241="Review Required",H241="Missing"),"Yes","No") -> No | S241: =IF(H241="Missing","Validate calibration evidence",IF(G241="Worsening","Review defect trend and containment",IF(I241="At Risk","Escalate supplier readiness","Continue monitoring"))) -> Continue monitoring

Sheet Weekly Trend
A1: Week Start | B1: Units Planned | C1: Units Produced | D1: Defects | E1: Defect Rate | F1: On-Time % | G1: Downtime Hours | H1: High Risk Records
A2: 46027 | B2: =SUMIFS('Operations Data'!$J:$J,'Operations Data'!$B:$B,A2) -> 17886 | C2: =SUMIFS('Operations Data'!$K:$K,'Operations Data'!$B:$B,A2) -> 17157 | D2: =SUMIFS('Operations Data'!$L:$L,'Operations Data'!$B:$B,A2) -> 418 | E2: =IFERROR(D2/C2,0) -> 0.024363234 | F2: =IFERROR(SUMIFS('Operations Data'!$N:$N,'Operations Data'!$B:$B,A2)/C2,0) -> 0.94352159 | G2: =SUMIFS('Operations Data'!$P:$P,'Operations Data'!$B:$B,A2) -> 104.3 | H2: =COUNTIFS('Operations Data'!$B:$B,A2,'Operations Data'!$AD:$AD,"High") -> 2
A3: 46034 | B3: =SUMIFS('Operations Data'!$J:$J,'Operations Data'!$B:$B,A3) -> 17032 | C3: =SUMIFS('Operations Data'!$K:$K,'Operations Data'!$B:$B,A3) -> 16713 | D3: =SUMIFS('Operations Data'!$L:$L,'Operations Data'!$B:$B,A3) -> 393 | E3: =IFERROR(D3/C3,0) -> 0.023514629 | F3: =IFERROR(SUMIFS('Operations Data'!$N:$N,'Operations Data'!$B:$B,A3)/C3,0) -> 0.94453419 | G3: =SUMIFS('Operations Data'!$P:$P,'Operations Data'!$B:$B,A3) -> 72.2 | H3: =COUNTIFS('Operations Data'!$B:$B,A3,'Operations Data'!$AD:$AD,"High") -> 1
A4: 46041 | B4: =SUMIFS('Operations Data'!$J:$J,'Operations Data'!$B:$B,A4) -> 17442 | C4: =SUMIFS('Operations Data'!$K:$K,'Operations Data'!$B:$B,A4) -> 17293 | D4: =SUMIFS('Operations Data'!$L:$L,'Operations Data'!$B:$B,A4) -> 474 | E4: =IFERROR(D4/C4,0) -> 0.027409935 | F4: =IFERROR(SUMIFS('Operations Data'!$N:$N,'Operations Data'!$B:$B,A4)/C4,0) -> 0.95425895 | G4: =SUMIFS('Operations Data'!$P:$P,'Operations Data'!$B:$B,A4) -> 106.8 | H4: =COUNTIFS('Operations Data'!$B:$B,A4,'Operations Data'!$AD:$AD,"High") -> 1
A5: 46048 | B5: =SUMIFS('Operations Data'!$J:$J,'Operations Data'!$B:$B,A5) -> 18359 | C5: =SUMIFS('Operations Data'!$K:$K,'Operations Data'!$B:$B,A5) -> 18227 | D5: =SUMIFS('Operations Data'!$L:$L,'Operations Data'!$B:$B,A5) -> 428 | E5: =IFERROR(D5/C5,0) -> 0.023481648 | F5: =IFERROR(SUMIFS('Operations Data'!$N:$N,'Operations Data'!$B:$B,A5)/C5,0) -> 0.94963516 | G5: =SUMIFS('Operations Data'!$P:$P,'Operations Data'!$B:$B,A5) -> 105.8 | H5: =COUNTIFS('Operations Data'!$B:$B,A5,'Operations Data'!$AD:$AD,"High") -> 0
A6: 46055 | B6: =SUMIFS('Operations Data'!$J:$J,'Operations Data'!$B:$B,A6) -> 16964 | C6: =SUMIFS('Operations Data'!$K:$K,'Operations Data'!$B:$B,A6) -> 16955 | D6: =SUMIFS('Operations Data'!$L:$L,'Operations Data'!$B:$B,A6) -> 383 | E6: =IFERROR(D6/C6,0) -> 0.022589207 | F6: =IFERROR(SUMIFS('Operations Data'!$N:$N,'Operations Data'!$B:$B,A6)/C6,0) -> 0.95924506 | G6: =SUMIFS('Operations Data'!$P:$P,'Operations Data'!$B:$B,A6) -> 115.7 | H6: =COUNTIFS('Operations Data'!$B:$B,A6,'Operations Data'!$AD:$AD,"High") -> 0
A7: 46062 | B7: =SUMIFS('Operations Data'!$J:$J,'Operations Data'!$B:$B,A7) -> 16896 | C7: =SUMIFS('Operations Data'!$K:$K,'Operations Data'!$B:$B,A7) -> 17162 | D7: =SUMIFS('Operations Data'!$L:$L,'Operations Data'!$B:$B,A7) -> 391 | E7: =IFERROR(D7/C7,0) -> 0.022782892 | F7: =IFERROR(SUMIFS('Operations Data'!$N:$N,'Operations Data'!$B:$B,A7)/C7,0) -> 0.92087169 | G7: =SUMIFS('Operations Data'!$P:$P,'Operations Data'!$B:$B,A7) -> 135.6 | H7: =COUNTIFS('Operations Data'!$B:$B,A7,'Operations Data'!$AD:$AD,"High") -> 1
A8: 46069 | B8: =SUMIFS('Operations Data'!$J:$J,'Operations Data'!$B:$B,A8) -> 18066 | C8: =SUMIFS('Operations Data'!$K:$K,'Operations Data'!$B:$B,A8) -> 18035 | D8: =SUMIFS('Operations Data'!$L:$L,'Operations Data'!$B:$B,A8) -> 444 | E8: =IFERROR(D8/C8,0) -> 0.024618797 | F8: =IFERROR(SUMIFS('Operations Data'!$N:$N,'Operations Data'!$B:$B,A8)/C8,0) -> 0.95542002 | G8: =SUMIFS('Operations Data'!$P:$P,'Operations Data'!$B:$B,A8) -> 150.2 | H8: =COUNTIFS('Operations Data'!$B:$B,A8,'Operations Data'!$AD:$AD,"High") -> 0
A9: 46076 | B9: =SUMIFS('Operations Data'!$J:$J,'Operations Data'!$B:$B,A9) -> 20084 | C9: =SUMIFS('Operations Data'!$K:$K,'Operations Data'!$B:$B,A9) -> 19898 | D9: =SUMIFS('Operations Data'!$L:$L,'Operations Data'!$B:$B,A9) -> 599 | E9: =IFERROR(D9/C9,0) -> 0.030103528 | F9: =IFERROR(SUMIFS('Operations Data'!$N:$N,'Operations Data'!$B:$B,A9)/C9,0) -> 0.93456629 | G9: =SUMIFS('Operations Data'!$P:$P,'Operations Data'!$B:$B,A9) -> 116.2 | H9: =COUNTIFS('Operations Data'!$B:$B,A9,'Operations Data'!$AD:$AD,"High") -> 0
A10: 46083 | B10: =SUMIFS('Operations Data'!$J:$J,'Operations Data'!$B:$B,A10) -> 16163 | C10: =SUMIFS('Operations Data'!$K:$K,'Operations Data'!$B:$B,A10) -> 16068 | D10: =SUMIFS('Operations Data'!$L:$L,'Operations Data'!$B:$B,A10) -> 399 | E10: =IFERROR(D10/C10,0) -> 0.024831964 | F10: =IFERROR(SUMIFS('Operations Data'!$N:$N,'Operations Data'!$B:$B,A10)/C10,0) -> 0.92867812 | G10: =SUMIFS('Operations Data'!$P:$P,'Operations Data'!$B:$B,A10) -> 159.2 | H10: =COUNTIFS('Operations Data'!$B:$B,A10,'Operations Data'!$AD:$AD,"High") -> 1
A11: 46090 | B11: =SUMIFS('Operations Data'!$J:$J,'Operations Data'!$B:$B,A11) -> 16651 | C11: =SUMIFS('Operations Data'!$K:$K,'Operations Data'!$B:$B,A11) -> 15955 | D11: =SUMIFS('Operations Data'!$L:$L,'Operations Data'!$B:$B,A11) -> 348 | E11: =IFERROR(D11/C11,0) -> 0.021811344 | F11: =IFERROR(SUMIFS('Operations Data'!$N:$N,'Operations Data'!$B:$B,A11)/C11,0) -> 0.94628643 | G11: =SUMIFS('Operations Data'!$P:$P,'Operations Data'!$B:$B,A11) -> 123.6 | H11: =COUNTIFS('Operations Data'!$B:$B,A11,'Operations Data'!$AD:$AD,"High") -> 0
A12: 46097 | B12: =SUMIFS('Operations Data'!$J:$J,'Operations Data'!$B:$B,A12) -> 18238 | C12: =SUMIFS('Operations Data'!$K:$K,'Operations Data'!$B:$B,A12) -> 17238 | D12: =SUMIFS('Operations Data'!$L:$L,'Operations Data'!$B:$B,A12) -> 424 | E12: =IFERROR(D12/C12,0) -> 0.024596821 | F12: =IFERROR(SUMIFS('Operations Data'!$N:$N,'Operations Data'!$B:$B,A12)/C12,0) -> 0.92974823 | G12: =SUMIFS('Operations Data'!$P:$P,'Operations Data'!$B:$B,A12) -> 106.9 | H12: =COUNTIFS('Operations Data'!$B:$B,A12,'Operations Data'!$AD:$AD,"High") -> 0
A13: 46104 | B13: =SUMIFS('Operations Data'!$J:$J,'Operations Data'!$B:$B,A13) -> 17831 | C13: =SUMIFS('Operations Data'!$K:$K,'Operations Data'!$B:$B,A13) -> 16673 | D13: =SUMIFS('Operations Data'!$L:$L,'Operations Data'!$B:$B,A13) -> 404 | E13: =IFERROR(D13/C13,0) -> 0.024230792 | F13: =IFERROR(SUMIFS('Operations Data'!$N:$N,'Operations Data'!$B:$B,A13)/C13,0) -> 0.9389432 | G13: =SUMIFS('Operations Data'!$P:$P,'Operations Data'!$B:$B,A13) -> 91.9 | H13: =COUNTIFS('Operations Data'!$B:$B,A13,'Operations Data'!$AD:$AD,"High") -> 2
... A41: 46300 | B41: =SUMIFS('Operations Data'!$J:$J,'Operations Data'!$B:$B,A41) -> 16934 | C41: =SUMIFS('Operations Data'!$K:$K,'Operations Data'!$B:$B,A41) -> 16418 | D41: =SUMIFS('Operations Data'!$L:$L,'Operations Data'!$B:$B,A41) -> 377 | E41: =IFERROR(D41/C41,0) -> 0.022962602 | F41: =IFERROR(SUMIFS('Operations Data'!$N:$N,'Operations Data'!$B:$B,A41)/C41,0) -> 0.93555853 | G41: =SUMIFS('Operations Data'!$P:$P,'Operations Data'!$B:$B,A41) -> 109.4 | H41: =COUNTIFS('Operations Data'!$B:$B,A41,'Operations Data'!$AD:$AD,"High") -> 0

Sheet Summary
A1: Executive Manufacturing Operations Summary
A3: Metric | B3: Value | D3: Metric | E3: Value
A4: Total Units Produced | B4: =SUM('Operations Data'!K2:K601) -> 657199 | D4: Leadership Attention Records | E4: =COUNTIF('Operations Data'!AE2:AE601,"Yes") -> 140
A5: Total Defects | B5: =SUM('Operations Data'!L2:L601) -> 16584 | D5: Late Supplier Confirmations | E5: =COUNTIF('Operations Data'!Q2:Q601,"Late") -> 85
A6: Overall Defect Rate | B6: =IFERROR(B5/B4,0) -> 0.025234366 | D6: Missing Calibration Records | E6: =COUNTIF('Operations Data'!R2:R601,"Yes") -> 12
A7: Overall On-Time % | B7: =IFERROR(SUM('Operations Data'!N2:N601)/B4,0) -> 0.94206017 | D7: Saturday Decisions Required | E7: =COUNTIF('Operations Data'!S2:S601,"Decision Required") -> 48
A8: Estimated Scrap Impact | B8: =SUM('Operations Data'!AB2:AB601) -> 4547805.1 | D8: Risk Reviews Required | E8: =COUNTIF('Quality Risk'!Q2:Q241,"Review Required") -> 115
A9: High Risk Records | B9: =COUNTIF('Operations Data'!AD2:AD601,"High") -> 36 | D9: Portfolio Exposure ($) | E9: =SUM('Quality Risk'!M2:M241) -> 327561856
A12: Plant | B12: Units Produced | C12: Defects | D12: Defect Rate | E12: On-Time % | F12: Scrap Impact ($) | G12: High Risk | H12: Leadership Attention
A13: Dearborn Assembly | B13: =SUMIFS('Operations Data'!$K:$K,'Operations Data'!$D:$D,A13) -> 133240 | C13: =SUMIFS('Operations Data'!$L:$L,'Operations Data'!$D:$D,A13) -> 3984 | D13: =IFERROR(C13/B13,0) -> 0.029900931 | E13: =IFERROR(SUMIFS('Operations Data'!$N:$N,'Operations Data'!$D:$D,A13)/B13,0) -> 0.9441384 | F13: =SUMIFS('Operations Data'!$AB:$AB,'Operations Data'!$D:$D,A13) -> 1511631.3 | G13: =COUNTIFS('Operations Data'!$D:$D,A13,'Operations Data'!$AD:$AD,"High") -> 9 | H13: =COUNTIFS('Operations Data'!$D:$D,A13,'Operations Data'!$AE:$AE,"Yes") -> 33
A14: Kansas City Assembly | B14: =SUMIFS('Operations Data'!$K:$K,'Operations Data'!$D:$D,A14) -> 150496 | C14: =SUMIFS('Operations Data'!$L:$L,'Operations Data'!$D:$D,A14) -> 3542 | D14: =IFERROR(C14/B14,0) -> 0.023535509 | E14: =IFERROR(SUMIFS('Operations Data'!$N:$N,'Operations Data'!$D:$D,A14)/B14,0) -> 0.94331411 | F14: =SUMIFS('Operations Data'!$AB:$AB,'Operations Data'!$D:$D,A14) -> 806670.46 | G14: =COUNTIFS('Operations Data'!$D:$D,A14,'Operations Data'!$AD:$AD,"High") -> 7 | H14: =COUNTIFS('Operations Data'!$D:$D,A14,'Operations Data'!$AE:$AE,"Yes") -> 29
A15: Louisville Assembly | B15: =SUMIFS('Operations Data'!$K:$K,'Operations Data'!$D:$D,A15) -> 108372 | C15: =SUMIFS('Operations Data'!$L:$L,'Operations Data'!$D:$D,A15) -> 2525 | D15: =IFERROR(C15/B15,0) -> 0.023299376 | E15: =IFERROR(SUMIFS('Operations Data'!$N:$N,'Operations Data'!$D:$D,A15)/B15,0) -> 0.94181154 | F15: =SUMIFS('Operations Data'!$AB:$AB,'Operations Data'!$D:$D,A15) -> 605787.3 | G15: =COUNTIFS('Operations Data'!$D:$D,A15,'Operations Data'!$AD:$AD,"High") -> 6 | H15: =COUNTIFS('Operations Data'!$D:$D,A15,'Operations Data'!$AE:$AE,"Yes") -> 27
A16: Michigan Assembly | B16: =SUMIFS('Operations Data'!$K:$K,'Operations Data'!$D:$D,A16) -> 136286 | C16: =SUMIFS('Operations Data'!$L:$L,'Operations Data'!$D:$D,A16) -> 3470 | D16: =IFERROR(C16/B16,0) -> 0.025461163 | E16: =IFERROR(SUMIFS('Operations Data'!$N:$N,'Operations Data'!$D:$D,A16)/B16,0) -> 0.94094038 | F16: =SUMIFS('Operations Data'!$AB:$AB,'Operations Data'!$D:$D,A16) -> 872908.22 | G16: =COUNTIFS('Operations Data'!$D:$D,A16,'Operations Data'!$AD:$AD,"High") -> 11 | H16: =COUNTIFS('Operations Data'!$D:$D,A16,'Operations Data'!$AE:$AE,"Yes") -> 30
A17: Oakville Assembly | B17: =SUMIFS('Operations Data'!$K:$K,'Operations Data'!$D:$D,A17) -> 127892 | C17: =SUMIFS('Operations Data'!$L:$L,'Operations Data'!$D:$D,A17) -> 3041 | D17: =IFERROR(C17/B17,0) -> 0.023777875 | E17: =IFERROR(SUMIFS('Operations Data'!$N:$N,'Operations Data'!$D:$D,A17)/B17,0) -> 0.93991024 | F17: =SUMIFS('Operations Data'!$AB:$AB,'Operations Data'!$D:$D,A17) -> 749964.96 | G17: =COUNTIFS('Operations Data'!$D:$D,A17,'Operations Data'!$AD:$AD,"High") -> 3 | H17: =COUNTIFS('Operations Data'!$D:$D,A17,'Operations Data'!$AE:$AE,"Yes") -> 21
A21: Vehicle Program | B21: Units Produced | C21: Defects | D21: Defect Rate | E21: Estimated Scrap Impact ($)
A22: Electric SUV | B22: =SUMIFS('Operations Data'!$K:$K,'Operations Data'!$F:$F,A22) -> 134333 | C22: =SUMIFS('Operations Data'!$L:$L,'Operations Data'!$F:$F,A22) -> 3283 | D22: =IFERROR(C22/B22,0) -> 0.024439267 | E22: =SUMIFS('Operations Data'!$AB:$AB,'Operations Data'!$F:$F,A22) -> 729756.39
A23: Pickup Truck | B23: =SUMIFS('Operations Data'!$K:$K,'Operations Data'!$F:$F,A23) -> 133010 | C23: =SUMIFS('Operations Data'!$L:$L,'Operations Data'!$F:$F,A23) -> 3612 | D23: =IFERROR(C23/B23,0) -> 0.027155853 | E23: =SUMIFS('Operations Data'!$AB:$AB,'Operations Data'!$F:$F,A23) -> 1389430.8
A24: Commercial Van | B24: =SUMIFS('Operations Data'!$K:$K,'Operations Data'!$F:$F,A24) -> 141399 | C24: =SUMIFS('Operations Data'!$L:$L,'Operations Data'!$F:$F,A24) -> 3477 | D24: =IFERROR(C24/B24,0) -> 0.02458999 | E24: =SUMIFS('Operations Data'!$AB:$AB,'Operations Data'!$F:$F,A24) -> 806014.27
A25: Performance SUV | B25: =SUMIFS('Operations Data'!$K:$K,'Operations Data'!$F:$F,A25) -> 117976 | C25: =SUMIFS('Operations Data'!$L:$L,'Operations Data'!$F:$F,A25) -> 3129 | D25: =IFERROR(C25/B25,0) -> 0.026522344 | E25: =SUMIFS('Operations Data'!$AB:$AB,'Operations Data'!$F:$F,A25) -> 828598.01
A26: Hybrid Utility | B26: =SUMIFS('Operations Data'!$K:$K,'Operations Data'!$F:$F,A26) -> 127963 | C26: =SUMIFS('Operations Data'!$L:$L,'Operations Data'!$F:$F,A26) -> 3012 | D26: =IFERROR(C26/B26,0) -> 0.023538054 | E26: =SUMIFS('Operations Data'!$AB:$AB,'Operations Data'!$F:$F,A26) -> 769040.6

Sheet Intentional Issues
A1: Issue Type | B1: Worksheet / Location | C1: What to Look For | D1: Expected Correction / Demo Outcome
A2: Vehicle Program | B2: Operations Data!F15 | C2: Electric Sport Utility | D2: Normalize to Electric SUV
A3: Vehicle Program | B3: Operations Data!F42 | C3: Pickup Truck with trailing space | D3: Normalize to Pickup Truck
A4: Supplier | B4: Operations Data!H89 | C4: Vector Embedded Systems | D4: Normalize to Vector Embedded
A5: Plant | B5: Operations Data!D145 | C5: Dearborn Assy | D5: Normalize to Dearborn Assembly
A6: Shift | B6: Operations Data!G222 | C6: Nights | D6: Normalize to Night
A7: Supplier | B7: Operations Data!H319 | C7: Blue Harbour Components | D7: Normalize to Blue Harbor Components
